<?xml version="1.0"?>
<robot xmlns:xacro="http://ros.org/wiki/xacro">

	<!-- <xacro:include filename="$(find soft_hand_description)/model/soft_hand.urdf.xacro"/> -->


	<xacro:property name="pi" value="3.1415926535897931"/>
	<xacro:property name="velocity" value="100"/>
	<xacro:property name="effort" value="100"/>

	<!-- link and joints -->
	<xacro:macro name="glove" params="parent name position orientation">
		<!-- revolute join x -->
		<joint name="${name}_erste_joint_roll" type="revolute">
			<origin xyz="${position}" rpy="${orientation}"/>
			<parent link="${parent}"/>
			<child link="${name}_erste_link_roll"/>
			<axis xyz="1 0 0"/>
			<limit lower="${0}" upper="${2*pi}" effort="${effort}" velocity="${velocity}"/>
		</joint>
			<!-- "fake" link -->
		<link name="${name}_erste_link_roll">
		</link>
		<!-- revolute jont y -->
		<joint name="${name}_erste_joint_pitch" type="revolute">
			<origin xyz="0 0 0" rpy="0 0 0"/>
			<parent link="${name}_erste_link_roll"/>
			<child link="${name}_erste_link_pitch"/>
			<axis xyz="0 1 0"/>
			<limit lower="${0}" upper="${2*pi}" effort="${effort}" velocity="${velocity}"/>
		</joint>
			<!-- "fake" link -->
		<link name="${name}_erste_link_pitch">
		</link>
		<!-- revolute joint z -->
		<joint name="${name}_erste_joint_yaw" type="revolute">
			<origin xyz="0 0 0" rpy="0 0 0"/>
			<parent link="${name}_erste_link_pitch"/>
			<child link="${name}_erste_link_yaw"/>
			<axis xyz="0 0 1"/>
			<limit lower="${0}" upper="${2*pi}" effort="${effort}" velocity="${velocity}"/>
		</joint>
		<!-- fake link -->
		<link name="${name}_erste_link_yaw">
		</link>



		<!-- prismatic joint x -->
		<joint name="${name}_erste_joint_x" type="prismatic">
			<origin xyz="${position}" rpy="${orientation}"/>
			<parent link="${name}_erste_link_yaw"/>
			<child link="${name}_erste_link_x"/>
			<axis xyz="1 0 0"/>
			<limit lower="${0}" upper="${2}" effort="${effort}" velocity="${velocity}"/>
		</joint>
		<!-- fake link -->
		<link name="${name}_erste_link_x">
		</link>
		<!-- prismatic joint y -->
		<joint name="${name}_erste_joint_y" type="prismatic">
			<origin xyz="0 0 0" rpy="0 0 0"/>
			<parent link="${name}_erste_link_x"/>
			<child link="${name}_erste_link_y"/>
			<axis xyz="0 1 0"/>
			<limit lower="${0}" upper="${2}" effort="${effort}" velocity="${velocity}"/>
		</joint>
		<!-- fake link -->
		<link name="${name}_erste_link_y">
		</link>
		<!-- prismatic joint z -->
		<joint name="${name}_erste_joint_z" type="prismatic">
			<origin xyz="0 0 0" rpy="0 0 0"/>
			<parent link="${name}_erste_link_y"/>
			<child link="${name}_erste_link_z"/>
			<axis xyz="0 0 1"/>
			<limit lower="${0}" upper="${2}" effort="${effort}" velocity="${velocity}"/>
		</joint>
		<!-- fake link -->
		<link name="${name}_erste_link_z">
		</link>

		<!-- fixed joint -->
		<joint name="glied" type="fixed">
			<origin xyz="0 0 0" rpy="0 0 0"/>
			<parent link="glove_erste_link_z"/>
			<child link="glied_link"/>
		</joint>
		<!-- real link -->
		<link name="glied_link">
			<visual>
				<origin xyz="0 0 0" rpy="0 ${pi/2} 0"/>
				<geometry>
					<box size="0.1 0.1 0.01"/>
				</geometry>
				<material name="Black"/>
			</visual>
		</link>

	
	</xacro:macro> 


</robot>












